{"uuid": "e1588fef-dac0-4980-af64-6eed77a80b21", "children": ["eedb9e3e-f17e-4023-9db5-2a9e5f5fc357"], "befores": [{"name": "browser", "status": "broken", "statusDetails": {"message": "selenium.common.exceptions.SessionNotCreatedException: Message: session not created: Chrome failed to start: exited normally.\n  (session not created: DevToolsActivePort file doesn't exist)\n  (The process started from chrome location /usr/bin/google-chrome is no longer running, so ChromeDriver is assuming that Chrome has crashed.)\nStacktrace:\n#0 0x59756009a863 <unknown>\n#1 0x59755fd908c6 <unknown>\n#2 0x59755fdc4d34 <unknown>\n#3 0x59755fdc0d3d <unknown>\n#4 0x59755fe09aed <unknown>\n#5 0x59755fdfd343 <unknown>\n#6 0x59755fdce593 <unknown>\n#7 0x59755fdcef5e <unknown>\n#8 0x59756005e84b <unknown>\n#9 0x5975600627a5 <unknown>\n#10 0x59756004c571 <unknown>\n#11 0x597560063332 <unknown>\n#12 0x59756003187f <unknown>\n#13 0x597560089728 <unknown>\n#14 0x5975600898fb <unknown>\n#15 0x5975600999b4 <unknown>\n#16 0x7fa224894ac3 <unknown>\n\n", "trace": "  File \"/usr/local/lib/python3.10/dist-packages/pluggy/_callers.py\", line 167, in _multicall\n    teardown.throw(outcome._exception)\n  File \"/usr/local/lib/python3.10/dist-packages/_pytest/setuponly.py\", line 36, in pytest_fixture_setup\n    return (yield)\n  File \"/usr/local/lib/python3.10/dist-packages/pluggy/_callers.py\", line 103, in _multicall\n    res = hook_impl.function(*args)\n  File \"/usr/local/lib/python3.10/dist-packages/_pytest/fixtures.py\", line 1125, in pytest_fixture_setup\n    result = call_fixture_func(fixturefunc, request, kwargs)\n  File \"/usr/local/lib/python3.10/dist-packages/_pytest/fixtures.py\", line 880, in call_fixture_func\n    fixture_result = next(generator)\n  File \"/home/fuenukkusu2501/Develop/tmp/OTUS_selenium_UI/conftest.py\", line 56, in browser\n    browser = webdriver.Chrome(service=Service(), options=options)\n  File \"/usr/local/lib/python3.10/dist-packages/selenium/webdriver/chrome/webdriver.py\", line 45, in __init__\n    super().__init__(\n  File \"/usr/local/lib/python3.10/dist-packages/selenium/webdriver/chromium/webdriver.py\", line 66, in __init__\n    super().__init__(command_executor=executor, options=options)\n  File \"/usr/local/lib/python3.10/dist-packages/selenium/webdriver/remote/webdriver.py\", line 208, in __init__\n    self.start_session(capabilities)\n  File \"/usr/local/lib/python3.10/dist-packages/selenium/webdriver/remote/webdriver.py\", line 292, in start_session\n    response = self.execute(Command.NEW_SESSION, caps)[\"value\"]\n  File \"/usr/local/lib/python3.10/dist-packages/selenium/webdriver/remote/webdriver.py\", line 347, in execute\n    self.error_handler.check_response(response)\n  File \"/usr/local/lib/python3.10/dist-packages/selenium/webdriver/remote/errorhandler.py\", line 229, in check_response\n    raise exception_class(message, screen, stacktrace)\n"}, "start": 1721316269549, "stop": 1721316269726}], "start": 1721316269549, "stop": 1721316269745}