{"uuid": "9178a10c-209d-4887-965f-8e8197297947", "children": ["12ae2f9f-7d0e-4304-82d4-eb13d5a3694c"], "befores": [{"name": "browser", "status": "broken", "statusDetails": {"message": "selenium.common.exceptions.SessionNotCreatedException: Message: session not created: Chrome failed to start: exited normally.\n  (session not created: DevToolsActivePort file doesn't exist)\n  (The process started from chrome location /usr/bin/google-chrome is no longer running, so ChromeDriver is assuming that Chrome has crashed.)\nStacktrace:\n#0 0x5c1beb7b6863 <unknown>\n#1 0x5c1beb4ac8c6 <unknown>\n#2 0x5c1beb4e0d34 <unknown>\n#3 0x5c1beb4dcd3d <unknown>\n#4 0x5c1beb525aed <unknown>\n#5 0x5c1beb519343 <unknown>\n#6 0x5c1beb4ea593 <unknown>\n#7 0x5c1beb4eaf5e <unknown>\n#8 0x5c1beb77a84b <unknown>\n#9 0x5c1beb77e7a5 <unknown>\n#10 0x5c1beb768571 <unknown>\n#11 0x5c1beb77f332 <unknown>\n#12 0x5c1beb74d87f <unknown>\n#13 0x5c1beb7a5728 <unknown>\n#14 0x5c1beb7a58fb <unknown>\n#15 0x5c1beb7b59b4 <unknown>\n#16 0x7dfee5e94ac3 <unknown>\n\n", "trace": "  File \"/usr/local/lib/python3.10/dist-packages/pluggy/_callers.py\", line 167, in _multicall\n    teardown.throw(outcome._exception)\n  File \"/usr/local/lib/python3.10/dist-packages/_pytest/setuponly.py\", line 36, in pytest_fixture_setup\n    return (yield)\n  File \"/usr/local/lib/python3.10/dist-packages/pluggy/_callers.py\", line 103, in _multicall\n    res = hook_impl.function(*args)\n  File \"/usr/local/lib/python3.10/dist-packages/_pytest/fixtures.py\", line 1125, in pytest_fixture_setup\n    result = call_fixture_func(fixturefunc, request, kwargs)\n  File \"/usr/local/lib/python3.10/dist-packages/_pytest/fixtures.py\", line 880, in call_fixture_func\n    fixture_result = next(generator)\n  File \"/home/fuenukkusu2501/Develop/tmp/OTUS_selenium_UI/conftest.py\", line 56, in browser\n    browser = webdriver.Chrome(service=Service(), options=options)\n  File \"/usr/local/lib/python3.10/dist-packages/selenium/webdriver/chrome/webdriver.py\", line 45, in __init__\n    super().__init__(\n  File \"/usr/local/lib/python3.10/dist-packages/selenium/webdriver/chromium/webdriver.py\", line 66, in __init__\n    super().__init__(command_executor=executor, options=options)\n  File \"/usr/local/lib/python3.10/dist-packages/selenium/webdriver/remote/webdriver.py\", line 208, in __init__\n    self.start_session(capabilities)\n  File \"/usr/local/lib/python3.10/dist-packages/selenium/webdriver/remote/webdriver.py\", line 292, in start_session\n    response = self.execute(Command.NEW_SESSION, caps)[\"value\"]\n  File \"/usr/local/lib/python3.10/dist-packages/selenium/webdriver/remote/webdriver.py\", line 347, in execute\n    self.error_handler.check_response(response)\n  File \"/usr/local/lib/python3.10/dist-packages/selenium/webdriver/remote/errorhandler.py\", line 229, in check_response\n    raise exception_class(message, screen, stacktrace)\n"}, "start": 1721316429284, "stop": 1721316429440}], "start": 1721316429284, "stop": 1721316429460}