{"uuid": "deb101c4-b3b9-4e72-903e-f7684e7431d6", "children": ["2d1d87e3-4736-4a55-a4e8-47f985707959"], "befores": [{"name": "browser", "status": "broken", "statusDetails": {"message": "urllib3.exceptions.MaxRetryError: HTTPConnectionPool(host='selenoid', port=4444): Max retries exceeded with url: /wd/hub/session (Caused by NewConnectionError('<urllib3.connection.HTTPConnection object at 0x727178bf2080>: Failed to establish a new connection: [Errno -3] Temporary failure in name resolution'))\n", "trace": "  File \"/home/fuenukkusu2501/.local/lib/python3.10/site-packages/pluggy/_callers.py\", line 167, in _multicall\n    teardown.throw(outcome._exception)\n  File \"/home/fuenukkusu2501/.local/lib/python3.10/site-packages/_pytest/setuponly.py\", line 36, in pytest_fixture_setup\n    return (yield)\n  File \"/home/fuenukkusu2501/.local/lib/python3.10/site-packages/pluggy/_callers.py\", line 103, in _multicall\n    res = hook_impl.function(*args)\n  File \"/home/fuenukkusu2501/.local/lib/python3.10/site-packages/_pytest/fixtures.py\", line 1132, in pytest_fixture_setup\n    result = call_fixture_func(fixturefunc, request, kwargs)\n  File \"/home/fuenukkusu2501/.local/lib/python3.10/site-packages/_pytest/fixtures.py\", line 913, in call_fixture_func\n    fixture_result = fixturefunc(**kwargs)\n  File \"/home/fuenukkusu2501/Develop/tmp/OTUS_selenium_UI/conftest.py\", line 121, in browser\n    driver = webdriver.Remote(\n  File \"/home/fuenukkusu2501/.local/lib/python3.10/site-packages/selenium/webdriver/remote/webdriver.py\", line 208, in __init__\n    self.start_session(capabilities)\n  File \"/home/fuenukkusu2501/.local/lib/python3.10/site-packages/selenium/webdriver/remote/webdriver.py\", line 292, in start_session\n    response = self.execute(Command.NEW_SESSION, caps)[\"value\"]\n  File \"/home/fuenukkusu2501/.local/lib/python3.10/site-packages/selenium/webdriver/remote/webdriver.py\", line 345, in execute\n    response = self.command_executor.execute(driver_command, params)\n  File \"/home/fuenukkusu2501/.local/lib/python3.10/site-packages/selenium/webdriver/remote/remote_connection.py\", line 302, in execute\n    return self._request(command_info[0], url, body=data)\n  File \"/home/fuenukkusu2501/.local/lib/python3.10/site-packages/selenium/webdriver/remote/remote_connection.py\", line 322, in _request\n    response = self._conn.request(method, url, body=body, headers=headers)\n  File \"/usr/lib/python3/dist-packages/urllib3/request.py\", line 78, in request\n    return self.request_encode_body(\n  File \"/usr/lib/python3/dist-packages/urllib3/request.py\", line 170, in request_encode_body\n    return self.urlopen(method, url, **extra_kw)\n  File \"/usr/lib/python3/dist-packages/urllib3/poolmanager.py\", line 375, in urlopen\n    response = conn.urlopen(method, u.request_uri, **kw)\n  File \"/usr/lib/python3/dist-packages/urllib3/connectionpool.py\", line 784, in urlopen\n    return self.urlopen(\n  File \"/usr/lib/python3/dist-packages/urllib3/connectionpool.py\", line 784, in urlopen\n    return self.urlopen(\n  File \"/usr/lib/python3/dist-packages/urllib3/connectionpool.py\", line 784, in urlopen\n    return self.urlopen(\n  File \"/usr/lib/python3/dist-packages/urllib3/connectionpool.py\", line 756, in urlopen\n    retries = retries.increment(\n  File \"/usr/lib/python3/dist-packages/urllib3/util/retry.py\", line 574, in increment\n    raise MaxRetryError(_pool, url, error or ResponseError(cause))\n"}, "start": 1723997715427, "stop": 1723997715431}], "start": 1723997715427, "stop": 1723997715519}