{"uuid": "b2730a35-39f6-4f68-a94d-9ea232ae8f95", "children": ["f4a5bb73-f067-42d1-8bdc-4366947bdede"], "befores": [{"name": "browser", "status": "broken", "statusDetails": {"message": "selenium.common.exceptions.SessionNotCreatedException: Message: session not created: Chrome failed to start: exited normally.\n  (session not created: DevToolsActivePort file doesn't exist)\n  (The process started from chrome location /usr/bin/google-chrome is no longer running, so ChromeDriver is assuming that Chrome has crashed.)\nStacktrace:\n#0 0x5d68c0736863 <unknown>\n#1 0x5d68c042c8c6 <unknown>\n#2 0x5d68c0460d34 <unknown>\n#3 0x5d68c045cd3d <unknown>\n#4 0x5d68c04a5aed <unknown>\n#5 0x5d68c0499343 <unknown>\n#6 0x5d68c046a593 <unknown>\n#7 0x5d68c046af5e <unknown>\n#8 0x5d68c06fa84b <unknown>\n#9 0x5d68c06fe7a5 <unknown>\n#10 0x5d68c06e8571 <unknown>\n#11 0x5d68c06ff332 <unknown>\n#12 0x5d68c06cd87f <unknown>\n#13 0x5d68c0725728 <unknown>\n#14 0x5d68c07258fb <unknown>\n#15 0x5d68c07359b4 <unknown>\n#16 0x7f9c56494ac3 <unknown>\n\n", "trace": "  File \"/usr/local/lib/python3.10/dist-packages/pluggy/_callers.py\", line 167, in _multicall\n    teardown.throw(outcome._exception)\n  File \"/usr/local/lib/python3.10/dist-packages/_pytest/setuponly.py\", line 36, in pytest_fixture_setup\n    return (yield)\n  File \"/usr/local/lib/python3.10/dist-packages/pluggy/_callers.py\", line 103, in _multicall\n    res = hook_impl.function(*args)\n  File \"/usr/local/lib/python3.10/dist-packages/_pytest/fixtures.py\", line 1125, in pytest_fixture_setup\n    result = call_fixture_func(fixturefunc, request, kwargs)\n  File \"/usr/local/lib/python3.10/dist-packages/_pytest/fixtures.py\", line 880, in call_fixture_func\n    fixture_result = next(generator)\n  File \"/home/fuenukkusu2501/Develop/tmp/OTUS_selenium_UI/conftest.py\", line 56, in browser\n    browser = webdriver.Chrome(service=Service(), options=options)\n  File \"/usr/local/lib/python3.10/dist-packages/selenium/webdriver/chrome/webdriver.py\", line 45, in __init__\n    super().__init__(\n  File \"/usr/local/lib/python3.10/dist-packages/selenium/webdriver/chromium/webdriver.py\", line 66, in __init__\n    super().__init__(command_executor=executor, options=options)\n  File \"/usr/local/lib/python3.10/dist-packages/selenium/webdriver/remote/webdriver.py\", line 208, in __init__\n    self.start_session(capabilities)\n  File \"/usr/local/lib/python3.10/dist-packages/selenium/webdriver/remote/webdriver.py\", line 292, in start_session\n    response = self.execute(Command.NEW_SESSION, caps)[\"value\"]\n  File \"/usr/local/lib/python3.10/dist-packages/selenium/webdriver/remote/webdriver.py\", line 347, in execute\n    self.error_handler.check_response(response)\n  File \"/usr/local/lib/python3.10/dist-packages/selenium/webdriver/remote/errorhandler.py\", line 229, in check_response\n    raise exception_class(message, screen, stacktrace)\n"}, "start": 1718696487504, "stop": 1718696487655}], "start": 1718696487504, "stop": 1718696487673}