{"uuid": "39e61daf-3bac-4ae2-a201-b94aa28d3814", "children": ["7ca66aa6-a41b-4a53-96af-3559ca2acfac"], "befores": [{"name": "browser", "status": "broken", "statusDetails": {"message": "selenium.common.exceptions.SessionNotCreatedException: Message: session not created: Chrome failed to start: exited normally.\n  (session not created: DevToolsActivePort file doesn't exist)\n  (The process started from chrome location /usr/bin/google-chrome is no longer running, so ChromeDriver is assuming that Chrome has crashed.)\nStacktrace:\n#0 0x5acdcd5b5863 <unknown>\n#1 0x5acdcd2ab8c6 <unknown>\n#2 0x5acdcd2dfd34 <unknown>\n#3 0x5acdcd2dbd3d <unknown>\n#4 0x5acdcd324aed <unknown>\n#5 0x5acdcd318343 <unknown>\n#6 0x5acdcd2e9593 <unknown>\n#7 0x5acdcd2e9f5e <unknown>\n#8 0x5acdcd57984b <unknown>\n#9 0x5acdcd57d7a5 <unknown>\n#10 0x5acdcd567571 <unknown>\n#11 0x5acdcd57e332 <unknown>\n#12 0x5acdcd54c87f <unknown>\n#13 0x5acdcd5a4728 <unknown>\n#14 0x5acdcd5a48fb <unknown>\n#15 0x5acdcd5b49b4 <unknown>\n#16 0x7699cd294ac3 <unknown>\n\n", "trace": "  File \"/usr/local/lib/python3.10/dist-packages/pluggy/_callers.py\", line 167, in _multicall\n    teardown.throw(outcome._exception)\n  File \"/usr/local/lib/python3.10/dist-packages/_pytest/setuponly.py\", line 36, in pytest_fixture_setup\n    return (yield)\n  File \"/usr/local/lib/python3.10/dist-packages/pluggy/_callers.py\", line 103, in _multicall\n    res = hook_impl.function(*args)\n  File \"/usr/local/lib/python3.10/dist-packages/_pytest/fixtures.py\", line 1125, in pytest_fixture_setup\n    result = call_fixture_func(fixturefunc, request, kwargs)\n  File \"/usr/local/lib/python3.10/dist-packages/_pytest/fixtures.py\", line 880, in call_fixture_func\n    fixture_result = next(generator)\n  File \"/home/fuenukkusu2501/Develop/tmp/OTUS_selenium_UI/conftest.py\", line 56, in browser\n    browser = webdriver.Chrome(service=Service(), options=options)\n  File \"/usr/local/lib/python3.10/dist-packages/selenium/webdriver/chrome/webdriver.py\", line 45, in __init__\n    super().__init__(\n  File \"/usr/local/lib/python3.10/dist-packages/selenium/webdriver/chromium/webdriver.py\", line 66, in __init__\n    super().__init__(command_executor=executor, options=options)\n  File \"/usr/local/lib/python3.10/dist-packages/selenium/webdriver/remote/webdriver.py\", line 208, in __init__\n    self.start_session(capabilities)\n  File \"/usr/local/lib/python3.10/dist-packages/selenium/webdriver/remote/webdriver.py\", line 292, in start_session\n    response = self.execute(Command.NEW_SESSION, caps)[\"value\"]\n  File \"/usr/local/lib/python3.10/dist-packages/selenium/webdriver/remote/webdriver.py\", line 347, in execute\n    self.error_handler.check_response(response)\n  File \"/usr/local/lib/python3.10/dist-packages/selenium/webdriver/remote/errorhandler.py\", line 229, in check_response\n    raise exception_class(message, screen, stacktrace)\n"}, "start": 1721317021495, "stop": 1721317021680}], "start": 1721317021495, "stop": 1721317021727}